Workbook

Sheet How to use
A1: DMET 502 Project 1: TMNT tower defense requirements
A3: Theme: players are the turtles (Leonardo = Melee, Raphael = Ranged, Donatello = Defense); enemies are Foot Soldiers (Easy), Bebop (Medium) and Rocksteady (Hard). Home base = the turtles' sewer Lair. Collectible = pizza.
A5: Tabs
A6: • Functional Requirements: every feature as a user story, with dependencies, spec section, priority, sprint, owner, effort, status and reviewer. Filter by Owner to get each person's list.
A7: • Non-functional Requirements: quality rules (modern OpenGL only, performance, robustness, UX, licensing).
A8: • Team Split: roles, names (fill in), workload per sprint (live formulas), sprint calendar and working rules.
A9: • TMNT Theme Bible: character roster with stats and design notes, environment elements, cutscene storyboard, palette.
A10: • Open Questions: spec ambiguities to ask the TA, with the default we build until answered.
A11: • Spec Coverage: how many requirements trace to each section of the project description, and progress per section.
A13: What to edit
A14: • Yellow cells: names on Team Split, TA answers on Open Questions. Owner name and Reviewer fill in automatically.
A15: • Status column (dropdown): Not started → In progress → Done → Tested (reviewer only) or Blocked.
... A19: Priority: Must = required by the spec · Bonus = sound bonus (all of §5 needed to earn it) · Optional = nice-to-have · Dev aid = testing helper.

Sheet Functional Requirements
A1: Req. No. | B1: Feature area | C1: Depends on | D1: As a [stakeholder] | E1: I should be able to [action] | F1: Extra comments / Rules you MUST follow | G1: Spec § | H1: Priority | I1: Sprint | J1: Owner | K1: Owner name | L1: Effort (pts) | M1: Status | N1: Reviewer
A2: 1 | B2: Engine & setup | C2: — | D2: Developer | E2: create the game window and a modern OpenGL 3.3+ core-profile context | F2: Use GLFW + GLAD (or GLEW) + GLM. Request the 3.3 core profile explicitly and print the GL version at startup. No fixed-function calls anywhere (glBegin/glEnd, glVertex, glColor, glMatrixMode, glPushMatrix): the spec requires modern OpenGL. | G2: §1 | H2: Must | I2: 1 | J2: A | K2: {=IFERROR(INDEX('Team Split'!$B$5:$B$8,MATCH(J2,'Team Split'!$A$5:$A$8,0))&"","")} | L2: 2 | M2: Not started | N2: {=IFERROR(INDEX('Team Split'!$F$5:$F$8,MATCH(J2,'Team Split'!$A$5:$A$8,0))&"","")} -> C
A3: 2 | B3: Engine & setup | C3: — | D3: Developer | E3: build the whole project from a clean checkout with one documented project file | F3: CMake or a Visual Studio solution with dependencies kept in /external. Confirm with the TA which OS/IDE they compile on. Any compilation error = zero for the project. | G3: §7 | H3: Must | I3: 1 | J3: A | K3: {=IFERROR(INDEX('Team Split'!$B$5:$B$8,MATCH(J3,'Team Split'!$A$5:$A$8,0))&"","")} | L3: 3 | M3: Not started | N3: {=IFERROR(INDEX('Team Split'!$F$5:$F$8,MATCH(J3,'Team Split'!$A$5:$A$8,0))&"","")} -> C
A4: 3 | B4: Engine & setup | C4: 1 | D4: Developer | E4: compile, link and use GLSL shaders with readable error logs | F4: Shader class: load from file, uniform setters (mat4, vec4, float, int). One flat-color shader with u_model, u_projection, u_color, u_tintAmount and u_grayscale covers characters, damage tint and locked cards. | G4: §1 | H4: Must | I4: 1 | J4: A | K4: {=IFERROR(INDEX('Team Split'!$B$5:$B$8,MATCH(J4,'Team Split'!$A$5:$A$8,0))&"","")} | L4: 2 | M4: Not started | N4: {=IFERROR(INDEX('Team Split'!$F$5:$F$8,MATCH(J4,'Team Split'!$A$5:$A$8,0))&"","")} -> C
A5: 4 | B5: Engine & setup | C5: 3 | D5: Developer | E5: draw in a fixed logical world (e.g., 1600 × 900 units) through an orthographic projection | F5: All gameplay coordinates are world units, never pixels. Handle window resize with letterboxing so lanes, mouse picking and the HUD stay aligned. | G5: §1 | H5: Must | I5: 1 | J5: A | K5: {=IFERROR(INDEX('Team Split'!$B$5:$B$8,MATCH(J5,'Team Split'!$A$5:$A$8,0))&"","")} | L5: 2 | M5: Not started | N5: {=IFERROR(INDEX('Team Split'!$F$5:$F$8,MATCH(J5,'Team Split'!$A$5:$A$8,0))&"","")} -> C
A6: 5 | B6: Engine & setup | C6: 1 | D6: Developer | E6: run a frame-rate-independent game loop driven by delta time | F6: All speeds in units/second and all timers in seconds. Clamp dt (≤ 0.05 s) so dragging the window doesn't teleport entities. Enable vsync. | G6: §1 | H6: Must | I6: 1 | J6: A | K6: {=IFERROR(INDEX('Team Split'!$B$5:$B$8,MATCH(J6,'Team Split'!$A$5:$A$8,0))&"","")} | L6: 1 | M6: Not started | N6: {=IFERROR(INDEX('Team Split'!$F$5:$F$8,MATCH(J6,'Team Split'!$A$5:$A$8,0))&"","")} -> C
A7: 6 | B7: Engine & setup | C7: 3 | D7: Developer | E7: draw reusable primitive meshes: quad, circle/ellipse, triangle, rounded rectangle, arc/ring, polygon and thick line | F7: Upload each mesh to a VAO/VBO once at startup and draw it with a model matrix + color. These are the building blocks of every model; never re-upload static geometry every frame. | G7: §1 | H7: Must | I7: 1 | J7: A | K7: {=IFERROR(INDEX('Team Split'!$B$5:$B$8,MATCH(J7,'Team Split'!$A$5:$A$8,0))&"","")} | L7: 3 | M7: Not started | N7: {=IFERROR(INDEX('Team Split'!$F$5:$F$8,MATCH(J7,'Team Split'!$A$5:$A$8,0))&"","")} -> C
A8: 7 | B8: Engine & setup | C8: 6 | D8: Developer | E8: compose models from parts using a transform hierarchy (matrix stack / scene-graph nodes) | F8: Each part has a local transform relative to its parent (hand → forearm → upper arm → torso), so one rotation animates the weapon in the hand. Needed for 'weapon animates in the character's hand'. | G8: §4.1 | H8: Must | I8: 1 | J8: D | K8: {=IFERROR(INDEX('Team Split'!$B$5:$B$8,MATCH(J8,'Team Split'!$A$5:$A$8,0))&"","")} | L8: 3 | M8: Not started | N8: {=IFERROR(INDEX('Team Split'!$F$5:$F$8,MATCH(J8,'Team Split'!$A$5:$A$8,0))&"","")} -> B
A9: 8 | B9: Engine & setup | C9: 3 | D9: Developer | E9: render text and numbers on screen | F9: Font atlas through stb_truetype or FreeType (extra libraries are allowed). Used by the coin counter, health numbers, card costs, wave banner, menu labels and cutscene subtitles. | G9: §4.2 | H9: Must | I9: 1 | J9: C | K9: {=IFERROR(INDEX('Team Split'!$B$5:$B$8,MATCH(J9,'Team Split'!$A$5:$A$8,0))&"","")} | L9: 3 | M9: Not started | N9: {=IFERROR(INDEX('Team Split'!$F$5:$F$8,MATCH(J9,'Team Split'!$A$5:$A$8,0))&"","")} -> A
A10: 9 | B10: Engine & setup | C10: 5 | D10: Developer | E10: switch between game states: Main Menu, Sound Settings, Cutscene, Playing, Paused, Win and Lose | F10: One state machine owns update/render dispatch. Paused, Win and Lose keep drawing the frozen scene under the menu but stop all gameplay updates. | G10: §4.3 | H10: Must | I10: 1 | J10: A | K10: {=IFERROR(INDEX('Team Split'!$B$5:$B$8,MATCH(J10,'Team Split'!$A$5:$A$8,0))&"","")} | L10: 2 | M10: Not started | N10: {=IFERROR(INDEX('Team Split'!$F$5:$F$8,MATCH(J10,'Team Split'!$A$5:$A$8,0))&"","")} -> C
A11: 10 | B11: Engine & setup | C11: 5 | D11: Developer | E11: manage turtles, villains, projectiles and collectibles through one shared Entity interface | F11: Fields: id, type, lane (const after creation), x, yOffset, width, height, hp, maxHp, state, alive. Virtual update(dt) and draw(). Dead entities are removed at the end of the frame, never while iterating. Agree this interface on day 1: everyone builds on it. | G11: §3.1 | H11: Must | I11: 1 | J11: A | K11: {=IFERROR(INDEX('Team Split'!$B$5:$B$8,MATCH(J11,'Team Split'!$A$5:$A$8,0))&"","")} | L11: 3 | M11: Not started | N11: {=IFERROR(INDEX('Team Split'!$F$5:$F$8,MATCH(J11,'Team Split'!$A$5:$A$8,0))&"","")} -> C
A12: 11 | B12: Engine & setup | C12: 4 | D12: Developer | E12: receive keyboard and mouse input and convert the cursor position to world coordinates | F12: GLFW callbacks for W, S, Up, Down, Esc, left click and cursor movement. Screen → world conversion must account for the letterboxing. | G12: §3.2 | H12: Must | I12: 1 | J12: C | K12: {=IFERROR(INDEX('Team Split'!$B$5:$B$8,MATCH(J12,'Team Split'!$A$5:$A$8,0))&"","")} | L12: 2 | M12: Not started | N12: {=IFERROR(INDEX('Team Split'!$F$5:$F$8,MATCH(J12,'Team Split'!$A$5:$A$8,0))&"","")} -> A
A13: 12 | B13: Engine & setup | C13: — | D13: Developer | E13: tune every gameplay number from one Config.h | F13: START_COINS, card costs, coin drop value, HP, damage, speeds, attack intervals, jump/duck timings, wave definitions, cutscene length. Rebalancing never touches logic code. | G13: §3.2 | H13: Must | I13: 1 | J13: A | K13: {=IFERROR(INDEX('Team Split'!$B$5:$B$8,MATCH(J13,'Team Split'!$A$5:$A$8,0))&"","")} | L13: 1 | M13: Not started | N13: {=IFERROR(INDEX('Team Split'!$F$5:$F$8,MATCH(J13,'Team Split'!$A$5:$A$8,0))&"","")} -> C
A14: 13 | B14: Engine & setup | C14: — | D14: Developer | E14: randomize lanes, enemy order and spawn timing with a seeded RNG | F14: std::mt19937. A debug flag fixes the seed so the video can be recorded reproducibly. | G14: §3.1 | H14: Must | I14: 1 | J14: A | K14: {=IFERROR(INDEX('Team Split'!$B$5:$B$8,MATCH(J14,'Team Split'!$A$5:$A$8,0))&"","")} | L14: 1 | M14: Not started | N14: {=IFERROR(INDEX('Team Split'!$F$5:$F$8,MATCH(J14,'Team Split'!$A$5:$A$8,0))&"","")} -> C
A15: 14 | B15: Engine & setup | C15: — | D15: Developer | E15: load shaders, fonts and sounds through relative paths | F15: No absolute paths (C:\Users\...). The TA must be able to build and run straight from the submitted zip. | G15: §7 | H15: Must | I15: 1 | J15: A | K15: {=IFERROR(INDEX('Team Split'!$B$5:$B$8,MATCH(J15,'Team Split'!$A$5:$A$8,0))&"","")} | L15: 1 | M15: Not started | N15: {=IFERROR(INDEX('Team Split'!$F$5:$F$8,MATCH(J15,'Team Split'!$A$5:$A$8,0))&"","")} -> C
A16: 15 | B16: Engine & setup | C16: 6 | D16: Player | E16: see everything drawn in a consistent order | F16: Background → environment → lanes and highlights → Lair → collectibles → characters → projectiles → health bars → HUD → menus. | G16: §4 | H16: Must | I16: 1 | J16: A | K16: {=IFERROR(INDEX('Team Split'!$B$5:$B$8,MATCH(J16,'Team Split'!$A$5:$A$8,0))&"","")} | L16: 1 | M16: Not started | N16: {=IFERROR(INDEX('Team Split'!$F$5:$F$8,MATCH(J16,'Team Split'!$A$5:$A$8,0))&"","")} -> C
A17: 16 | B17: Engine & setup | C17: 8 | D17: Developer | E17: toggle a debug overlay showing FPS, lane bounds and hitboxes | F17: F1 toggles it. Off by default in the submitted build. | G17: §1 | H17: Dev aid | I17: 1 | J17: C | K17: {=IFERROR(INDEX('Team Split'!$B$5:$B$8,MATCH(J17,'Team Split'!$A$5:$A$8,0))&"","")} | L17: 1 | M17: Not started | N17: {=IFERROR(INDEX('Team Split'!$F$5:$F$8,MATCH(J17,'Team Split'!$A$5:$A$8,0))&"","")} -> A
A18: 17 | B18: Engine & setup | C18: 9 | D18: Developer | E18: use debug keys to add coins, skip to a wave, kill all enemies or force a loss | F18: Speeds up testing and recording the video. Disable or document them before submission. | G18: §6 | H18: Dev aid | I18: 2 | J18: A | K18: {=IFERROR(INDEX('Team Split'!$B$5:$B$8,MATCH(J18,'Team Split'!$A$5:$A$8,0))&"","")} | L18: 1 | M18: Not started | N18: {=IFERROR(INDEX('Team Split'!$F$5:$F$8,MATCH(J18,'Team Split'!$A$5:$A$8,0))&"","")} -> C
A19: 18 | B19: Menus & game flow | C19: 8, 11 | D19: Player | E19: see menu buttons react when I hover over and click them | F19: One Button component (hover = highlight/scale, press = pressed state) reused in all three menus so the UI is consistent. | G19: §4.3 | H19: Must | I19: 1 | J19: C | K19: {=IFERROR(INDEX('Team Split'!$B$5:$B$8,MATCH(J19,'Team Split'!$A$5:$A$8,0))&"","")} | L19: 2 | M19: Not started | N19: {=IFERROR(INDEX('Team Split'!$F$5:$F$8,MATCH(J19,'Team Split'!$A$5:$A$8,0))&"","")} -> A
A20: 19 | B20: Menus & game flow | C20: 18, 9 | D20: Player | E20: see the Main Menu when the game launches, before the cutscene | F20: Themed screen (sewer background, game title, turtle silhouettes), not a plain rectangle. | G20: §4.3 | H20: Must | I20: 1 | J20: C | K20: {=IFERROR(INDEX('Team Split'!$B$5:$B$8,MATCH(J20,'Team Split'!$A$5:$A$8,0))&"","")} | L20: 2 | M20: Not started | N20: {=IFERROR(INDEX('Team Split'!$F$5:$F$8,MATCH(J20,'Team Split'!$A$5:$A$8,0))&"","")} -> A
A21: 20 | B21: Menus & game flow | C21: 19 | D21: Player | E21: click Start to play the cutscene and then start the game | F21: Start → Cutscene → Playing. Every start creates a fresh game state (coins = START_COINS, wave 1, no entities). | G21: §4.3 | H21: Must | I21: 1 | J21: C | K21: {=IFERROR(INDEX('Team Split'!$B$5:$B$8,MATCH(J21,'Team Split'!$A$5:$A$8,0))&"","")} | L21: 1 | M21: Not started | N21: {=IFERROR(INDEX('Team Split'!$F$5:$F$8,MATCH(J21,'Team Split'!$A$5:$A$8,0))&"","")} -> A
A22: 21 | B22: Menus & game flow | C22: 19 | D22: Player | E22: click Exit to close the application | F22: glfwSetWindowShouldClose; free GL and audio resources; no crash on exit. | G22: §4.3 | H22: Must | I22: 1 | J22: C | K22: {=IFERROR(INDEX('Team Split'!$B$5:$B$8,MATCH(J22,'Team Split'!$A$5:$A$8,0))&"","")} | L22: 1 | M22: Not started | N22: {=IFERROR(INDEX('Team Split'!$F$5:$F$8,MATCH(J22,'Team Split'!$A$5:$A$8,0))&"","")} -> A
A23: 22 | B23: Menus & game flow | C23: 19 | D23: Player | E23: open the Sound Settings from the Main Menu | F23: Bonus. The button must be on the Main Menu to qualify (§5). | G23: §5 | H23: Bonus | I23: 3 | J23: C | K23: {=IFERROR(INDEX('Team Split'!$B$5:$B$8,MATCH(J23,'Team Split'!$A$5:$A$8,0))&"","")} | L23: 1 | M23: Not started | N23: {=IFERROR(INDEX('Team Split'!$F$5:$F$8,MATCH(J23,'Team Split'!$A$5:$A$8,0))&"","")} -> A
A24: 23 | B24: Menus & game flow | C24: 9 | D24: Player | E24: press Esc during gameplay to open the Pause Menu | F24: Only in the Playing state. While paused nothing moves: entities, projectiles, spawn and wave timers and animations all freeze. | G24: §4.3 | H24: Must | I24: 2 | J24: C | K24: {=IFERROR(INDEX('Team Split'!$B$5:$B$8,MATCH(J24,'Team Split'!$A$5:$A$8,0))&"","")} | L24: 2 | M24: Not started | N24: {=IFERROR(INDEX('Team Split'!$F$5:$F$8,MATCH(J24,'Team Split'!$A$5:$A$8,0))&"","")} -> A
A25: 24 | B25: Menus & game flow | C25: 23 | D25: Player | E25: click Continue to resume exactly where I left off | F25: Pressing Esc again may also resume (optional). Timers resume without a jump. | G25: §4.3 | H25: Must | I25: 2 | J25: C | K25: {=IFERROR(INDEX('Team Split'!$B$5:$B$8,MATCH(J25,'Team Split'!$A$5:$A$8,0))&"","")} | L25: 1 | M25: Not started | N25: {=IFERROR(INDEX('Team Split'!$F$5:$F$8,MATCH(J25,'Team Split'!$A$5:$A$8,0))&"","")} -> A
A26: 25 | B26: Menus & game flow | C26: 23, 10 | D26: Player | E26: click Restart in the Pause or Win/Lose menu to start a new game | F26: Full reset: coins, wave, spawn queue, all entities, lane selections, card selection, collectibles and music. Assumption: Restart skips the cutscene (see Open Questions). | G26: §4.3 | H26: Must | I26: 2 | J26: A | K26: {=IFERROR(INDEX('Team Split'!$B$5:$B$8,MATCH(J26,'Team Split'!$A$5:$A$8,0))&"","")} | L26: 2 | M26: Not started | N26: {=IFERROR(INDEX('Team Split'!$F$5:$F$8,MATCH(J26,'Team Split'!$A$5:$A$8,0))&"","")} -> C
A27: 26 | B27: Menus & game flow | C27: 23 | D27: Player | E27: click Return to Main Menu in the Pause or Win/Lose menu | F27: Resets the game; pressing Start again replays the cutscene. | G27: §4.3 | H27: Must | I27: 2 | J27: C | K27: {=IFERROR(INDEX('Team Split'!$B$5:$B$8,MATCH(J27,'Team Split'!$A$5:$A$8,0))&"","")} | L27: 1 | M27: Not started | N27: {=IFERROR(INDEX('Team Split'!$F$5:$F$8,MATCH(J27,'Team Split'!$A$5:$A$8,0))&"","")} -> A
A28: 27 | B28: Menus & game flow | C28: 9 | D28: Player | E28: see a Win/Lose Menu when I win or lose | F28: Themed 'Lair Defended!' / 'The Lair Has Fallen' message over the frozen scene, with Restart and Return to Main Menu. | G28: §4.3 | H28: Must | I28: 2 | J28: C | K28: {=IFERROR(INDEX('Team Split'!$B$5:$B$8,MATCH(J28,'Team Split'!$A$5:$A$8,0))&"","")} | L28: 2 | M28: Not started | N28: {=IFERROR(INDEX('Team Split'!$F$5:$F$8,MATCH(J28,'Team Split'!$A$5:$A$8,0))&"","")} -> A
A29: 28 | B29: Menus & game flow | C29: 8 | D29: Player | E29: see a short controls legend (lanes, cards, W/S, Esc) | F29: Not required by the spec, but it helps graders and the video. Put it in the Pause Menu or as a small HUD hint. | G29: §4.3 | H29: Optional | I29: 3 | J29: C | K29: {=IFERROR(INDEX('Team Split'!$B$5:$B$8,MATCH(J29,'Team Split'!$A$5:$A$8,0))&"","")} | L29: 1 | M29: Not started | N29: {=IFERROR(INDEX('Team Split'!$F$5:$F$8,MATCH(J29,'Team Split'!$A$5:$A$8,0))&"","")} -> A
A30: 29 | B30: Cutscene | C30: — | D30: Team member | E30: agree a 10–20 s cutscene script and storyboard | F30: See the 'TMNT Theme Bible' tab for beats, timing and dialogue. Lock it by the end of Sprint 1 so modeling and animation can start. | G30: §2 | H30: Must | I30: 1 | J30: D | K30: {=IFERROR(INDEX('Team Split'!$B$5:$B$8,MATCH(J30,'Team Split'!$A$5:$A$8,0))&"","")} | L30: 1 | M30: Not started | N30: {=IFERROR(INDEX('Team Split'!$F$5:$F$8,MATCH(J30,'Team Split'!$A$5:$A$8,0))&"","")} -> B
A31: 30 | B31: Cutscene | C31: 7 | D31: Developer | E31: animate cutscene actors and the camera with a keyframe timeline | F31: Tracks for position, rotation, scale, alpha and visibility with linear and ease-in-out interpolation. Camera pan/zoom by animating the view matrix. | G31: §2 | H31: Must | I31: 2 | J31: D | K31: {=IFERROR(INDEX('Team Split'!$B$5:$B$8,MATCH(J31,'Team Split'!$A$5:$A$8,0))&"","")} | L31: 3 | M31: Not started | N31: {=IFERROR(INDEX('Team Split'!$F$5:$F$8,MATCH(J31,'Team Split'!$A$5:$A$8,0))&"","")} -> B
A32: 31 | B32: Cutscene | C32: 30, 20 | D32: Player | E32: watch a fully animated 10–20 second cutscene after pressing Start | F32: Target 16 s. Log the measured duration in debug builds to prove it stays between 10 and 20 s. Transitions into gameplay automatically. | G32: §2 | H32: Must | I32: 2 | J32: D | K32: {=IFERROR(INDEX('Team Split'!$B$5:$B$8,MATCH(J32,'Team Split'!$A$5:$A$8,0))&"","")} | L32: 2 | M32: Not started | N32: {=IFERROR(INDEX('Team Split'!$F$5:$F$8,MATCH(J32,'Team Split'!$A$5:$A$8,0))&"","")} -> B
A33: 32 | B33: Cutscene | C33: 31, 69, 85 | D33: Player | E33: see at least one turtle and one villain visibly animated and interacting on screen | F33: Reuse the gameplay model functions (consistency, less work). Walk cycles, gestures, weapon draws and a clash. Never static images. | G33: §2 | H33: Must | I33: 3 | J33: D | K33: {=IFERROR(INDEX('Team Split'!$B$5:$B$8,MATCH(J33,'Team Split'!$A$5:$A$8,0))&"","")} | L33: 3 | M33: Not started | N33: {=IFERROR(INDEX('Team Split'!$F$5:$F$8,MATCH(J33,'Team Split'!$A$5:$A$8,0))&"","")} -> B
A34: 33 | B34: Cutscene | C34: 31, 8 | D34: Player | E34: follow a short dialogue between the turtles and the villains | F34: Subtitle bar or speech bubbles timed on the timeline; the speaker bobs and gestures while their line shows. The story must still read with the text hidden: no text-only storytelling. | G34: §2 | H34: Must | I34: 2 | J34: D | K34: {=IFERROR(INDEX('Team Split'!$B$5:$B$8,MATCH(J34,'Team Split'!$A$5:$A$8,0))&"","")} | L34: 2 | M34: Not started | N34: {=IFERROR(INDEX('Team Split'!$F$5:$F$8,MATCH(J34,'Team Split'!$A$5:$A$8,0))&"","")} -> B
A35: 34 | B35: Cutscene | C35: 29 | D35: Player | E35: understand what the turtles are defending and why it matters | F35: Show the Lair (the home base) with the last mutagen canister inside. Rocksteady and Bebop lead the Foot Clan to seize it for Shredder; the dialogue says why losing it matters. | G35: §2 | H35: Must | I35: 2 | J35: D | K35: {=IFERROR(INDEX('Team Split'!$B$5:$B$8,MATCH(J35,'Team Split'!$A$5:$A$8,0))&"","")} | L35: 1 | M35: Not started | N35: {=IFERROR(INDEX('Team Split'!$F$5:$F$8,MATCH(J35,'Team Split'!$A$5:$A$8,0))&"","")} -> B
A36: 35 | B36: Cutscene | C36: 31, 111 | D36: Player | E36: recognize the NYC sewer setting from the cutscene | F36: Open with an establishing pan through the sewer tunnel using the same environment elements as the game scene. | G36: §2 | H36: Must | I36: 3 | J36: D | K36: {=IFERROR(INDEX('Team Split'!$B$5:$B$8,MATCH(J36,'Team Split'!$A$5:$A$8,0))&"","")} | L36: 2 | M36: Not started | N36: {=IFERROR(INDEX('Team Split'!$F$5:$F$8,MATCH(J36,'Team Split'!$A$5:$A$8,0))&"","")} -> B
A37: 36 | B37: Cutscene | C37: 31 | D37: Player | E37: see a smooth transition from the cutscene into gameplay | F37: Fade or iris wipe to the playfield. The last shot frames the Lair as it looks in-game, so the hand-off is logical. | G37: §2 | H37: Must | I37: 3 | J37: D | K37: {=IFERROR(INDEX('Team Split'!$B$5:$B$8,MATCH(J37,'Team Split'!$A$5:$A$8,0))&"","")} | L37: 1 | M37: Not started | N37: {=IFERROR(INDEX('Team Split'!$F$5:$F$8,MATCH(J37,'Team Split'!$A$5:$A$8,0))&"","")} -> B
A38: 37 | B38: Cutscene | C38: 31 | D38: Player | E38: skip the cutscene with Space or Enter | F38: Optional. Ask the TA first whether a skip is acceptable. | G38: §2 | H38: Optional | I38: 3 | J38: D | K38: {=IFERROR(INDEX('Team Split'!$B$5:$B$8,MATCH(J38,'Team Split'!$A$5:$A$8,0))&"","")} | L38: 1 | M38: Not started | N38: {=IFERROR(INDEX('Team Split'!$F$5:$F$8,MATCH(J38,'Team Split'!$A$5:$A$8,0))&"","")} -> B
A39: 38 | B39: Cutscene | C39: 32 | D39: Team member | E39: include Michelangelo (and Splinter) in the cutscene | F39: Optional cameo. The spec allows exactly three player types, so the fourth turtle appears only in the cutscene and menu. The required story works without them. | G39: §2 | H39: Optional | I39: 3 | J39: D | K39: {=IFERROR(INDEX('Team Split'!$B$5:$B$8,MATCH(J39,'Team Split'!$A$5:$A$8,0))&"","")} | L39: 2 | M39: Not started | N39: {=IFERROR(INDEX('Team Split'!$F$5:$F$8,MATCH(J39,'Team Split'!$A$5:$A$8,0))&"","")} -> B
A40: 39 | B40: Playfield & lanes | C40: 4, 6 | D40: Player | E40: see a side-view playfield of at least 3 horizontal lanes | F40: Default 4 lanes (configurable, minimum 3). Each lane is an independent battle line, drawn as a sewer walkway with visible separators. | G40: §3.1 | H40: Must | I40: 1 | J40: A | K40: {=IFERROR(INDEX('Team Split'!$B$5:$B$8,MATCH(J40,'Team Split'!$A$5:$A$8,0))&"","")} | L40: 2 | M40: Not started | N40: {=IFERROR(INDEX('Team Split'!$F$5:$F$8,MATCH(J40,'Team Split'!$A$5:$A$8,0))&"","")} -> C
...

Sheet Non-functional Requirements
A1: Non-functional requirements
A2: Quality rules that apply across all features. Status is tracked the same way as the functional sheet.
A4: Req. No. | B4: Category | C4: Requirement | D4: How we check it | E4: Sprint | F4: Owner | G4: Priority | H4: Status
A5: NF1 | B5: Graphics API | C5: Use only modern OpenGL 3.3+ (shaders, VAOs/VBOs). No deprecated fixed-function calls anywhere. | D5: Search the code for glBegin, glVertex, glColor3, glMatrixMode, glPushMatrix: zero hits. | E5: 1 | F5: A | G5: Must | H5: Not started
A6: NF2 | B6: Build | C6: The project compiles with zero errors on the TAs' environment from the submitted zip. | D6: Clean-machine build in Sprint 1 and again in Sprint 4. | E6: 4 | F6: A | G6: Must | H6: Not started
A7: NF3 | B7: Performance | C7: Hold 60 FPS with 30+ entities on screen on a lab-grade PC. | D7: Debug overlay FPS during a busy wave 3. | E7: 3 | F7: A | G7: Must | H7: Not started
A8: NF4 | B8: Performance | C8: Static meshes are uploaded once; only uniforms change per frame. | D8: Code review of the draw path. | E8: 1 | F8: A | G8: Must | H8: Not started
A9: NF5 | B9: Frame independence | C9: Movement, attacks and animations run at the same real-time speed at 30, 60 and 144 Hz. | D9: Toggle vsync off/on and compare a turtle crossing a lane. | E9: 1 | F9: A | G9: Must | H9: Not started
A10: NF6 | B10: Memory | C10: Entities and GL objects are freed; memory doesn't grow across restarts. | D10: Restart 10× and watch memory in Task Manager. | E10: 4 | F10: B | G10: Must | H10: Not started
A11: NF7 | B11: Robustness | C11: No crash under spam clicks, key mashing, many turtles in one lane, rapid pause/resume, resize or minimize. | D11: Stress checklist (functional req. 'survive stress cases'). | E11: 4 | F11: B | G11: Must | H11: Not started
A12: NF8 | B12: Resolution | C12: Layout, picking and text stay correct at 1280×720, 1920×1080 and after resizing. | D12: Manual check at both sizes. | E12: 2 | F12: C | G12: Must | H12: Not started
A13: NF9 | B13: Portability | C13: All asset paths are relative; nothing depends on a team member's machine. | D13: Run from a freshly unzipped folder. | E13: 1 | F13: A | G13: Must | H13: Not started
A14: NF10 | B14: Code quality | C14: One class/file pair per system (Game, LaneManager, Entity, Turtle, Villain, Projectile, WaveManager, UI, Menu, Cutscene, Models, Audio); tunables only in Config.h; no magic numbers. | D14: Peer review before merging to main. | E14: 1 | F14: All | G14: Must | H14: Not started
A15: NF11 | B15: Version control | C15: Git repo with one branch per member; main always builds; merge at least daily. | D15: Main builds after every merge. | E15: 1 | F15: All | G15: Must | H15: Not started
A16: NF12 | B16: UX: Feedback | C16: Every click and key press gives a visible response within one frame (hover, press, highlight, jump). | D16: Play-test checklist. | E16: 2 | F16: C | G16: Must | H16: Not started
... A24: NF20 | B24: Licensing | C24: Original or royalty-free/CC0 audio and fonts only; no TMNT theme song, official logo or ripped sprites (the video may be published online). | D24: Credits list in the README. | E24: 3 | F24: C | G24: Must | H24: Not started

Sheet Team Split
A1: Team split: who owns what
A2: Split by system so people rarely edit the same files. Fill in names in the yellow cells; the Owner name column on the requirements sheet updates automatically.
A4: Member | B4: Name (fill in) | C4: Role | D4: Owns | E4: Main files | F4: Reviews work of
A5: A | C5: Engine & game rules | D5: Window, shaders, primitive meshes, game loop, state machine, Entity system, lanes, waves, economy (coins/buying/drops), win/lose/freeze, Restart. Bebop & Rocksteady models and villain animations. Build, zip and submission. | E5: main.cpp, Game, Shader, Mesh, LaneManager, Entity, WaveManager, Economy, Config.h, VillainModels | F5: C
A6: B | C6: Combat & character logic | D6: Collision, movement, spawning positions, attacks and projectiles, jump/duck/dodge, Donatello protection, damage/tint/death, every turtle's and villain's behavior, effects, balancing and stress/regression testing. | E6: Collision, Turtle, Villain, Projectile, Effects | F6: D
A7: C | C7: UI, input, menus & audio | D7: Text rendering, input, lane hover/select, cards with lock/unlock and placement, pizza counter, health bars, HUD, all three menus, half the environment, the sound bonus, recording and editing the video. | E7: Text, Input, UI, HealthBar, Menu, Audio, Environment (part) | F7: A
A8: D | C8: Art, models & cutscene | D8: Transform hierarchy, Leonardo/Raphael/Donatello/Foot Soldier models and animations, the Lair, sewer background and part of the environment, pizza model, the whole cutscene, theme reviews, video script and title cards, README. | E8: Hierarchy, TurtleModels, FootModel, LairModel, Background, Cutscene, Timeline | F8: B
A10: Workload by sprint (effort points, calculated from the requirements sheet)
A11: Member | B11: Sprint 1 | C11: Sprint 2 | D11: Sprint 3 | E11: Sprint 4 | F11: Total pts | G11: # reqs | H11: Share | I11: Done pts | J11: % done
A12: A | B12: =SUMIFS('Functional Requirements'!$L:$L,'Functional Requirements'!$J:$J,$A12,'Functional Requirements'!$I:$I,1) -> 25 | C12: =SUMIFS('Functional Requirements'!$L:$L,'Functional Requirements'!$J:$J,$A12,'Functional Requirements'!$I:$I,2) -> 26 | D12: =SUMIFS('Functional Requirements'!$L:$L,'Functional Requirements'!$J:$J,$A12,'Functional Requirements'!$I:$I,3) -> 12 | E12: =SUMIFS('Functional Requirements'!$L:$L,'Functional Requirements'!$J:$J,$A12,'Functional Requirements'!$I:$I,4) -> 5 | F12: =SUM(B12:E12) -> 68 | G12: =COUNTIF('Functional Requirements'!$J:$J,$A12) -> 39 | H12: =IFERROR(F12/$F$16,0) -> 0.25954198 | I12: =SUMIFS('Functional Requirements'!$L:$L,'Functional Requirements'!$J:$J,$A12,'Functional Requirements'!$M:$M,"Done")+SUMIFS('Functional Requirements'!$L:$L,'Functional Requirements'!$J:$J,$A12,'Functional Requirements'!$M:$M,"Tested") -> 0 | J12: =IFERROR(I12/F12,0) -> 0
A13: B | B13: =SUMIFS('Functional Requirements'!$L:$L,'Functional Requirements'!$J:$J,$A13,'Functional Requirements'!$I:$I,1) -> 18 | C13: =SUMIFS('Functional Requirements'!$L:$L,'Functional Requirements'!$J:$J,$A13,'Functional Requirements'!$I:$I,2) -> 33 | D13: =SUMIFS('Functional Requirements'!$L:$L,'Functional Requirements'!$J:$J,$A13,'Functional Requirements'!$I:$I,3) -> 10 | E13: =SUMIFS('Functional Requirements'!$L:$L,'Functional Requirements'!$J:$J,$A13,'Functional Requirements'!$I:$I,4) -> 4 | F13: =SUM(B13:E13) -> 65 | G13: =COUNTIF('Functional Requirements'!$J:$J,$A13) -> 35 | H13: =IFERROR(F13/$F$16,0) -> 0.2480916 | I13: =SUMIFS('Functional Requirements'!$L:$L,'Functional Requirements'!$J:$J,$A13,'Functional Requirements'!$M:$M,"Done")+SUMIFS('Functional Requirements'!$L:$L,'Functional Requirements'!$J:$J,$A13,'Functional Requirements'!$M:$M,"Tested") -> 0 | J13: =IFERROR(I13/F13,0) -> 0
A14: C | B14: =SUMIFS('Functional Requirements'!$L:$L,'Functional Requirements'!$J:$J,$A14,'Functional Requirements'!$I:$I,1) -> 20 | C14: =SUMIFS('Functional Requirements'!$L:$L,'Functional Requirements'!$J:$J,$A14,'Functional Requirements'!$I:$I,2) -> 22 | D14: =SUMIFS('Functional Requirements'!$L:$L,'Functional Requirements'!$J:$J,$A14,'Functional Requirements'!$I:$I,3) -> 18 | E14: =SUMIFS('Functional Requirements'!$L:$L,'Functional Requirements'!$J:$J,$A14,'Functional Requirements'!$I:$I,4) -> 6 | F14: =SUM(B14:E14) -> 66 | G14: =COUNTIF('Functional Requirements'!$J:$J,$A14) -> 40 | H14: =IFERROR(F14/$F$16,0) -> 0.2519084 | I14: =SUMIFS('Functional Requirements'!$L:$L,'Functional Requirements'!$J:$J,$A14,'Functional Requirements'!$M:$M,"Done")+SUMIFS('Functional Requirements'!$L:$L,'Functional Requirements'!$J:$J,$A14,'Functional Requirements'!$M:$M,"Tested") -> 0 | J14: =IFERROR(I14/F14,0) -> 0
A15: D | B15: =SUMIFS('Functional Requirements'!$L:$L,'Functional Requirements'!$J:$J,$A15,'Functional Requirements'!$I:$I,1) -> 15 | C15: =SUMIFS('Functional Requirements'!$L:$L,'Functional Requirements'!$J:$J,$A15,'Functional Requirements'!$I:$I,2) -> 27 | D15: =SUMIFS('Functional Requirements'!$L:$L,'Functional Requirements'!$J:$J,$A15,'Functional Requirements'!$I:$I,3) -> 18 | E15: =SUMIFS('Functional Requirements'!$L:$L,'Functional Requirements'!$J:$J,$A15,'Functional Requirements'!$I:$I,4) -> 3 | F15: =SUM(B15:E15) -> 63 | G15: =COUNTIF('Functional Requirements'!$J:$J,$A15) -> 28 | H15: =IFERROR(F15/$F$16,0) -> 0.24045802 | I15: =SUMIFS('Functional Requirements'!$L:$L,'Functional Requirements'!$J:$J,$A15,'Functional Requirements'!$M:$M,"Done")+SUMIFS('Functional Requirements'!$L:$L,'Functional Requirements'!$J:$J,$A15,'Functional Requirements'!$M:$M,"Tested") -> 0 | J15: =IFERROR(I15/F15,0) -> 0
A16: Total | B16: =SUM(B12:B15) -> 78 | C16: =SUM(C12:C15) -> 108 | D16: =SUM(D12:D15) -> 58 | E16: =SUM(E12:E15) -> 18 | F16: =SUM(F12:F15) -> 262 | G16: =SUM(G12:G15) -> 142 | H16: =SUM(H12:H15) -> 1 | I16: =SUM(I12:I15) -> 0 | J16: =IFERROR(I16/F16,0) -> 0
A17: 1 pt ≈ 1–2 focused hours. Rebalance by changing Owner or Sprint on the requirements sheet; this table recalculates.
A19: Sprint calendar (deadline: Mon 2 Nov 2026, 11:59 PM)
A20: Sprint | B20: Dates | C20: Goal | E20: Exit criteria (demo to the team at the end)
A21: 1 | B21: Sat 17 – Wed 21 Oct | C21: Foundations: OpenGL setup, shapes, hierarchy, Entity interface, lanes, input, lane hover/select, text, main menu, first turtle models, movement and jumping on placeholder boxes. | E21: Main Menu → Start shows the lane grid; clicking selects lanes; boxes spawn, walk, jump and duck; Leonardo model renders.
A22: 2 | B22: Thu 22 – Mon 26 Oct | C22: Core game: combat, projectiles, every character's behavior and most models, Donatello protection, cards and coins, waves, collectibles, win/lose, pause and win/lose menus, cutscene first pass. | E22: A full run from wave 1 to a win and to a loss is playable with real models.
A23: 3 | B23: Tue 27 – Thu 29 Oct | C23: Polish and bonus: environment elements, effects, damage tint, Rocksteady model and villain animations, cutscene final, sound bonus, theme and distinctness reviews, balancing. Feature freeze Thu night. | E23: Every Must row is Done; reviewers start marking Tested.
A24: 4 | B24: Fri 30 Oct – Mon 2 Nov | C24: Test and ship: stress + regression testing, clean-machine build, video recording and editing, zip, Drive, form. Internal deadline Sun 1 Nov, 9 PM. | E24: Form submitted, video link submitted, confirmation received.
A27: Working rules
A28: 1. Day 1 (Sat 17 / Sun 18 Oct): agree the Entity interface, Config.h names and the shape/hierarchy API together. Everyone builds on them.
A29: 2. Build gameplay with placeholder boxes first; D swaps in real models through one draw function per character, so logic never waits for art.
A30: 3. One Git branch per member, merge to main at least daily, and main must always build.
A31: 4. Pairs review each other (A↔C, B↔D). Only the reviewer moves a row from Done to Tested.
A32: 5. Unanswered TA questions: build the default from the 'Open Questions' tab and keep the value in Config.h so it's a one-line change.

Sheet TMNT Theme Bible
A1: Shell Shock: Defend the Lair (working title)
A2: Story: Shredder wants the last canister of mutagen, hidden in the turtles' sewer Lair, to build a mutant army. Rocksteady and Bebop lead the Foot Clan through the tunnels; the turtles must hold every lane. If any villain reaches the Lair, the mutagen is lost.
A4: Spec role | B4: Character | C4: Weapon / attack | D4: Health | E4: Damage | F4: Speed | G4: Cost / unlock (default) | H4: Visual design (must differ by shape, not color) | I4: Model parts (minimum) | J4: Animations
A5: Player: Melee | B5: Leonardo | C5: Two katanas, close-range slash | D5: 5 lives | E5: 1 | F5: Normal | G5: 10 (unlocked at start) | H5: Slim balanced stance, blue mask, katanas crossed on the back and drawn when attacking. | I5: Shell + plate pattern, plastron, head, mask + tails, eyes, arms, hands, legs, pads, belt, 2 katanas (blade, guard, hilt) | J5: Idle bob, walk cycle, katana swing (arm joint), jump, duck, hit, defeat
A6: Player: Ranged | B6: Raphael | C6: Throws spinning sai (projectile) | D6: 5 lives | E6: 1 | F6: Normal | G6: 60 = 2 × 30 (see OQ 1) | H6: Bulkier, hunched, red mask, sai on belt, wind-up throwing pose. | I6: Same turtle base + red mask, sai holster, sai in hand, wrist wraps, scowl brow | J6: Idle, walk, throw (wind-up/release), sai spin in flight, impact flash
A7: Player: Defense | B7: Donatello | C7: None: blocks with a manhole-cover shield + bo staff | D7: 7 hits | E7: 0 | F7: Stationary | G7: 90 = 3 × 30 (see OQ 1) | H7: Wide planted stance, purple mask, tall bo staff, round manhole-cover shield, goggles on head. | I7: Turtle base + shield (rim, bolts), bo staff with wraps, goggles, knee pads | J7: Idle guard sway, block recoil, defeat
A8: Enemy: Easy (upper ranged) | B8: Foot Soldier | C8: Throws shuriken HIGH → turtles duck | D8: 5 lives | E8: 1 | F8: Normal | G8: Drops 15 pizza | H8: Lean human ninja: hood, eye-slit mask, Foot emblem, armor plates, dark purple/black, angular shapes. | I8: Hood, mask, eye slit, torso armor, emblem, arms, legs, belt, pouch, shuriken | J8: Walk, throw (overhead arm), hit, defeat
A9: Enemy: Medium (lower ranged) | B9: Bebop | C9: Blaster fires LOW shots → turtles jump | D9: 5 lives | E9: 1 | F9: Normal | G9: Drops 15 pizza | H9: Round bulky warthog: mohawk, tusks, sunglasses, vest, arm blaster. | I9: Head, snout, tusks, mohawk, glasses, belly, vest, arms, blaster, legs, boots | J9: Walk, blaster recoil, hit, defeat
A10: Enemy: Hard (melee) | B10: Rocksteady | C10: Charging punch / horn butt | D10: 7 lives | E10: 2 | F10: Fast (≈1.8×) | G10: Drops 15 pizza | H10: Largest villain: rhino head with horn, helmet, heavy shoulder armor, big fists. | I10: Head, horn, helmet, ears, armor plates, arms, fists, belt, legs, dust puffs | J10: Run, punch, hit, defeat
A11: Cutscene only (optional) | B11: Michelangelo, Splinter | C11: — | D11: — | E11: — | F11: — | G11: — | H11: Mikey: orange mask, nunchaku. Splinter: robe, walking staff. Shredder is only mentioned in dialogue, so he needs no model. | I11: Reuse the turtle base for Mikey | J11: Gestures, talking bob
A13: Environment elements (spec needs ≥ 5)
A14: # | B14: Element | C14: Details | H14: Where | I14: Owner
A15: 1 | B15: Sewer pipes | C15: Joints, valves, rust bands, animated drips | H15: Top wall, behind lanes | I15: C
A16: 2 | B16: Mutagen barrels | C16: Bands, hazard symbol, pulsing green ooze | H16: Near lane ends, between lanes | I16: D
A17: 3 | B17: Manhole covers & drain grates | C17: Bolted rings, slots | H17: Flat on the walkways | I17: A
A18: 4 | B18: Hanging work lamps | C18: Cage, bulb, light cone, flicker | H18: Ceiling | I18: A
A19: 5 | B19: Brick wall with graffiti + lair sign | C19: Brick pattern, original tags | H19: Back wall | I19: C
A20: 6 | B20: Pizza boxes & crates | C20: Stacked boxes, crate planks | H20: Next to the Lair | I20: A
A21: 7 | B21: Sewer-water stream | C21: Scrolling ripple lines | H21: Bottom channel | I21: C
A22: — | B22: The Lair (home base) | C22: Vault door with shell emblem, pipes, lights; spans all lanes | H22: Left edge | I22: D
A24: Cutscene storyboard (target 16 s; must stay 10–20 s)
A25: Time | B25: Shot | C25: On screen (animation) | H25: Dialogue / subtitle | I25: Spec point covered
A26: 0–3 s | B26: Establishing pan | C26: Camera glides through the sewer tunnel (pipes, lamps, water) to the Lair door; the mutagen canister glows inside. | H26: — | I26: Setting + what is defended
A27: 3–6 s | B27: Inside the Lair | C27: Leonardo and Raphael stand guard by the canister; Donatello reinforces the door. (Optional: Michelangelo grabs pizza, Splinter watches.) | H27: Leonardo: "Last canister of mutagen. In the wrong hands, it makes monsters." | I27: Why it matters
A28: 6–9 s | B28: Invasion | C28: Rumble, dust falls; a manhole bursts open on the right; Foot Soldiers drop in; Rocksteady and Bebop stomp out of the dust. | H28: Rocksteady: "Shredder wants that mutagen. Smash everything!" | I28: Enemies introduced, conflict
A29: 9–12 s | B29: Standoff | C29: Leonardo draws his katanas; Donatello slams his manhole shield down; Bebop raises his blaster. | H29: Leonardo: "You'll have to get through us first." / Bebop: "Easy!" | I29: Players + enemies interacting
A30: 12–15 s | B30: Clash | C30: Raphael throws a sai that knocks a Foot Soldier's shuriken out of the air; both sides fall back into their lanes. | H30: Raphael: "Next one's not a warning." | I30: Animated interaction
A31: 15–16 s | B31: Transition | C31: Camera pulls back to the playfield framing; iris wipe into gameplay. | H31: Leonardo: "Turtles, defend the Lair!" | I31: Logical lead-in to gameplay
A32: Dialogue lines are original placeholders; rewrite them freely, but keep them short and keep the story readable from the animation alone.
A34: Palette (keep turtles and villains in clearly separate families)
A35: Use | B35: Hex | C35: Swatch
A36: Turtle skin | B36: #4C9A2A
A37: Shell | B37: #7A5C2E
A38: Plastron | B38: #D8C27A
A39: Leonardo mask | B39: #1F5FBF
A40: Raphael mask | B40: #C0262D
A41: Donatello mask | B41: #7B3FA0
A42: Foot Clan | B42: #2B1F33
A43: Bebop / Rocksteady | B43: #6E6E6E
A44: Mutagen glow | B44: #7CFC00
...

Sheet Open Questions
A1: Open questions for the TA
A2: Ambiguities in the spec. Build the default now (as a Config.h value where possible) and update when the TA answers.
A4: # | B4: Topic | C4: Question for the TA | D4: Why it's unclear | E4: Our default until answered | F4: Affects reqs | G4: TA answer (fill in) | H4: Status
A5: 1 | B5: Unlock costs | C5: What exact pizza values should unlock Raphael (Ranged) and Donatello (Defense)? | D5: Start = enough for 3 Melee, and only Melee starts unlocked. If Ranged = 2 × Melee's price (2 × 10 = 20) and Defense = 3 × 10 = 30, both are affordable with the 30 starting coins, so they'd start unlocked. That contradicts 'all locked except Melee'. | E5: Base = the 30 starting coins (pizza) that unlock Leonardo: Leonardo 10 per placement, Raphael 60, Donatello 90; drop 15 per villain. | F5: 59, 74, 78, 64 | H5: Open
A6: 2 | B6: Placement with several lanes selected | C6: If several lanes are selected when a card is clicked, where does the turtle go? | D6: Placement needs a selected lane, but jump/duck lets you select several lanes at once. | E6: Place one turtle in the most recently selected lane. | F6: 66 | H6: Open
A7: 3 | B7: Right edge | C7: What happens when a turtle reaches the right edge with no enemy? | D7: The spec says turtles move 'until they reach the right' but not what follows. | E7: Walks off-screen and is removed. | F7: 46 | H7: Open
A8: 4 | B8: Dodging melee | C8: Can jump/duck dodge Rocksteady's melee attack? | D8: Only HIGH (duck) and LOW (jump) ranged attacks are defined. | E8: No: melee hits always land. | F8: 90, 58 | H8: Open
A9: 5 | B9: Duck input | C9: Is duck held while S/Down is pressed, or a fixed-time action like jump? | D9: The spec says 'while pressing S'. | E9: Held, with a minimum duration. | F9: 57 | H9: Open
A10: 6 | B10: Defense durability | C10: Does Rocksteady's 2-damage hit remove 2 of Donatello's 7 'hits'? | D10: Defense durability is given in hits, other units in lives. | E10: Treat all as HP: Rocksteady removes 2. | F10: 78 | H10: Open
A11: 7 | B11: Ranged villains meeting turtles | C11: Do Foot Soldiers and Bebop stop when they collide with a turtle? | D11: They attack from a distance, but the general rule says both stop on contact. | E11: Yes, the contact rule applies to every villain. | F11: 48 | H11: Open
A12: 8 | B12: Villains overlapping | C12: Can villains in the same lane pass through each other (e.g., a fast Rocksteady behind a fighting Foot Soldier)? | D12: The spec lets players overlap but says nothing about enemies. | E12: Yes, villains overlap like turtles do. | F12: 51 | H12: Open
A13: 9 | B13: Restart | C13: Should Restart replay the cutscene? | D13: The spec only says Start triggers the cutscene. | E13: No: Restart jumps straight into gameplay; Main Menu → Start replays it. | F13: 25 | H13: Open
A14: 10 | B14: Cutscene skip | C14: Is a skip key allowed? | D14: Not mentioned. | E14: Optional skip on Space/Enter, only if allowed. | F14: 37 | H14: Open
A15: 11 | B15: Zip contents | C15: May the zip include shaders, fonts, sounds and third-party libraries? | D15: 'Only .h, .cpp, … files' but the game needs these to run. | E15: Include them; exclude build outputs. | F15: 140 | H15: Open
A16: 12 | B16: Build environment | C16: Which OS/IDE do the TAs compile on (e.g., Windows + Visual Studio)? | D16: Compile errors = zero, so the target environment matters. | E16: Windows + Visual Studio via CMake. | F16: 2, 139 | H16: Open
... A19: 15 | B19: Franchise theme | C19: Is a TMNT-based theme OK, given the video may be published online? | D19: Existing characters, not an original theme. | E19: Use it with original models, original dialogue and royalty-free audio; no official logo or theme song. | F19: 125, 136 | H19: Open

Sheet Spec Coverage
A1: Spec coverage
A2: Every section of the project description and how many requirements trace to it. All numbers are formulas over the requirements sheet.
A4: Spec § | B4: Section | C4: What it requires | D4: # reqs | E4: Effort (pts) | F4: Done or Tested | G4: % done
A5: §1 | B5: Overview | C5: 2D side-view tower defense, own creative theme, modern OpenGL 3.3+, team of 3–4. | D5: =COUNTIF('Functional Requirements'!$G:$G,$A5) -> 6 | E5: =SUMIF('Functional Requirements'!$G:$G,$A5,'Functional Requirements'!$L:$L) -> 11 | F5: =COUNTIFS('Functional Requirements'!$G:$G,$A5,'Functional Requirements'!$M:$M,"Done")+COUNTIFS('Functional Requirements'!$G:$G,$A5,'Functional Requirements'!$M:$M,"Tested") -> 0 | G5: =IFERROR(F5/D5,0) -> 0
A6: §2 | B6: Cutscene | C6: Fully animated 10–20 s intro with ≥1 player and ≥1 enemy interacting, dialogue, what's defended and why; not text only. | D6: =COUNTIF('Functional Requirements'!$G:$G,$A6) -> 10 | E6: =SUMIF('Functional Requirements'!$G:$G,$A6,'Functional Requirements'!$L:$L) -> 18 | F6: =COUNTIFS('Functional Requirements'!$G:$G,$A6,'Functional Requirements'!$M:$M,"Done")+COUNTIFS('Functional Requirements'!$G:$G,$A6,'Functional Requirements'!$M:$M,"Tested") -> 0 | G6: =IFERROR(F6/D6,0) -> 0
A7: §3.1 | B7: Playfield | C7: ≥3 lanes, home base left, enemies enter right in random lanes, lane lock, auto-advance, auto-attack, stop-and-fight on contact, overlapping attacks. | D7: =COUNTIF('Functional Requirements'!$G:$G,$A7) -> 16 | E7: =SUMIF('Functional Requirements'!$G:$G,$A7,'Functional Requirements'!$L:$L) -> 27 | F7: =COUNTIFS('Functional Requirements'!$G:$G,$A7,'Functional Requirements'!$M:$M,"Done")+COUNTIFS('Functional Requirements'!$G:$G,$A7,'Functional Requirements'!$M:$M,"Tested") -> 0 | G7: =IFERROR(F7/D7,0) -> 0
A8: §3.2 | B8: Player logic | C8: Melee/Ranged/Defense, purchase with coins, lane hover/select (multi), W/S jump/duck, dodge rules, tint/scale damage, removal, overlap, Defense protection, damage values. | D8: =COUNTIF('Functional Requirements'!$G:$G,$A8) -> 24 | E8: =SUMIF('Functional Requirements'!$G:$G,$A8,'Functional Requirements'!$L:$L) -> 46 | F8: =COUNTIFS('Functional Requirements'!$G:$G,$A8,'Functional Requirements'!$M:$M,"Done")+COUNTIFS('Functional Requirements'!$G:$G,$A8,'Functional Requirements'!$M:$M,"Tested") -> 0 | G8: =IFERROR(F8/D8,0) -> 0
A9: §3.3 | B9: Enemy logic | C9: Easy/Medium/Hard behaviors and lives, damage values, 3 waves (3/5/10, type mix), wave start/end rules, drops and collection, distinct designs, tint, health. | D9: =COUNTIF('Functional Requirements'!$G:$G,$A9) -> 15 | E9: =SUMIF('Functional Requirements'!$G:$G,$A9,'Functional Requirements'!$L:$L) -> 28 | F9: =COUNTIFS('Functional Requirements'!$G:$G,$A9,'Functional Requirements'!$M:$M,"Done")+COUNTIFS('Functional Requirements'!$G:$G,$A9,'Functional Requirements'!$M:$M,"Tested") -> 0 | G9: =IFERROR(F9/D9,0) -> 0
A10: §3.4 | B10: Winning & losing | C10: Win after all waves are cleared; lose when any enemy reaches the base; everything stops. | D10: =COUNTIF('Functional Requirements'!$G:$G,$A10) -> 5 | E10: =SUMIF('Functional Requirements'!$G:$G,$A10,'Functional Requirements'!$L:$L) -> 6 | F10: =COUNTIFS('Functional Requirements'!$G:$G,$A10,'Functional Requirements'!$M:$M,"Done")+COUNTIFS('Functional Requirements'!$G:$G,$A10,'Functional Requirements'!$M:$M,"Tested") -> 0 | G10: =IFERROR(F10/D10,0) -> 0
A11: §4 | B11: Visuals | C11: Theme logically and realistically consistent across cutscene, story, environment, characters, weapons. | D11: =COUNTIF('Functional Requirements'!$G:$G,$A11) -> 4 | E11: =SUMIF('Functional Requirements'!$G:$G,$A11,'Functional Requirements'!$L:$L) -> 5 | F11: =COUNTIFS('Functional Requirements'!$G:$G,$A11,'Functional Requirements'!$M:$M,"Done")+COUNTIFS('Functional Requirements'!$G:$G,$A11,'Functional Requirements'!$M:$M,"Tested") -> 0 | G11: =IFERROR(F11/D11,0) -> 0
A12: §4.1 | B12: Enemies & players | C12: Players vs enemies and types within each group differ beyond color; health always visible; detailed models. | D12: =COUNTIF('Functional Requirements'!$G:$G,$A12) -> 11 | E12: =SUMIF('Functional Requirements'!$G:$G,$A12,'Functional Requirements'!$L:$L) -> 39 | F12: =COUNTIFS('Functional Requirements'!$G:$G,$A12,'Functional Requirements'!$M:$M,"Done")+COUNTIFS('Functional Requirements'!$G:$G,$A12,'Functional Requirements'!$M:$M,"Tested") -> 0 | G12: =IFERROR(F12/D12,0) -> 0
A13: §4.2 | B13: Game scene & UI | C13: ≥5 integrated environment elements; coin counter at top; player cards with grayscale lock, hover rules, auto unlock/relock. | D13: =COUNTIF('Functional Requirements'!$G:$G,$A13) -> 18 | E13: =SUMIF('Functional Requirements'!$G:$G,$A13,'Functional Requirements'!$L:$L) -> 32 | F13: =COUNTIFS('Functional Requirements'!$G:$G,$A13,'Functional Requirements'!$M:$M,"Done")+COUNTIFS('Functional Requirements'!$G:$G,$A13,'Functional Requirements'!$M:$M,"Tested") -> 0 | G13: =IFERROR(F13/D13,0) -> 0
A14: §4.3 | B14: Game menus | C14: Main Menu (Start, Exit, sound bonus), Pause Menu on Esc (Continue, Restart, Main Menu), Win/Lose Menu (Restart, Main Menu). | D14: =COUNTIF('Functional Requirements'!$G:$G,$A14) -> 11 | E14: =SUMIF('Functional Requirements'!$G:$G,$A14,'Functional Requirements'!$L:$L) -> 17 | F14: =COUNTIFS('Functional Requirements'!$G:$G,$A14,'Functional Requirements'!$M:$M,"Done")+COUNTIFS('Functional Requirements'!$G:$G,$A14,'Functional Requirements'!$M:$M,"Tested") -> 0 | G14: =IFERROR(F14/D14,0) -> 0
A15: §5 | B15: Bonus: sound | C15: Background music, ≥4 interaction SFX, Sound Settings menu from Main Menu with volume up/down/mute. | D15: =COUNTIF('Functional Requirements'!$G:$G,$A15) -> 7 | E15: =SUMIF('Functional Requirements'!$G:$G,$A15,'Functional Requirements'!$L:$L) -> 10 | F15: =COUNTIFS('Functional Requirements'!$G:$G,$A15,'Functional Requirements'!$M:$M,"Done")+COUNTIFS('Functional Requirements'!$G:$G,$A15,'Functional Requirements'!$M:$M,"Tested") -> 0 | G15: =IFERROR(F15/D15,0) -> 0
A16: §6 | B16: Video | C16: 2–5 min screen recording with voiceover in the required title sequence. | D16: =COUNTIF('Functional Requirements'!$G:$G,$A16) -> 6 | E16: =SUMIF('Functional Requirements'!$G:$G,$A16,'Functional Requirements'!$L:$L) -> 9 | F16: =COUNTIFS('Functional Requirements'!$G:$G,$A16,'Functional Requirements'!$M:$M,"Done")+COUNTIFS('Functional Requirements'!$G:$G,$A16,'Functional Requirements'!$M:$M,"Tested") -> 0 | G16: =IFERROR(F16/D16,0) -> 0
A17: §7 | B17: Submission | C17: No compile errors, source-only zip with the naming convention, Drive access, form, deadline. | D17: =COUNTIF('Functional Requirements'!$G:$G,$A17) -> 9 | E17: =SUMIF('Functional Requirements'!$G:$G,$A17,'Functional Requirements'!$L:$L) -> 14 | F17: =COUNTIFS('Functional Requirements'!$G:$G,$A17,'Functional Requirements'!$M:$M,"Done")+COUNTIFS('Functional Requirements'!$G:$G,$A17,'Functional Requirements'!$M:$M,"Tested") -> 0 | G17: =IFERROR(F17/D17,0) -> 0
B18: Total | D18: =SUM(D5:D17) -> 142 | E18: =SUM(E5:E17) -> 262 | F18: =SUM(F5:F17) -> 0 | G18: =IFERROR(F18/D18,0) -> 0
